Workbook
Name Slicer_التاريخ: #N/A
Name Slicer_المنتج_المناسب: #N/A
Name Slicer_مصدر_العميل: #N/A

Sheet dashboard

Sheet Sheet2
AP2: Row Labels
H3: Row Labels | I3: Count of استجابة العميل | K3: Row Labels | L3: Count of استجابة العميل | N3: Row Labels | O3: Count of استجابة العميل | Q3: Row Labels | R3: Count of استجابة العميل | T3: Row Labels | U3: Count of الاسم | W3: Row Labels | X3: Count of الجوال | AG3: Row Labels | AH3: Count of الاسم | AP3: 2025
H4: استجاب | I4: 26 | J4: =GETPIVOTDATA("استجابة العميل",$H$3,"استجابة العميل","استجاب") -> 26 | K4: استجاب | L4: 0.65 | M4: =GETPIVOTDATA("استجابة العميل",$K$3,"استجابة العميل","استجاب") -> 0.65 | N4: الائتمان | O4: 1 | Q4: الائتمان | R4: 0.025 | T4: CRM | U4: 6 | W4: ايجارة | X4: 12 | AG4: الرقم غير صحيح | AH4: 4 | AP4: <01/09/2025
H5: غبر مهم | I5: 7 | K5: غبر مهم | L5: 0.175 | N5: التحقق | O5: 1 | Q5: التحقق | R5: 0.025 | T5: اتصال وارد | U5: 3 | W5: تمويل إضافي | X5: 13 | AG5: المتابعة لاحقاً | AH5: 5 | AP5: <01/09/2025
H6: لم يستجب | I6: 7 | K6: لم يستجب | L6: 0.175 | N6: بانتظار المستندات | O6: 2 | Q6: بانتظار المستندات | R6: 0.05 | T6: إحالة من عميل | U6: 11 | W6: تمويل شخصي | X6: 5 | AG6: غير مهتم | AH6: 3 | AP6: Grand Total
H7: (blank) | K7: (blank) | L7: 0 | N7: تم التسليم | O7: 16 | Q7: تم التسليم | R7: 0.4 | T7: بحث شخصي | U7: 4 | W7: شراء مديونية | X7: 10 | AG7: لم يرد | AH7: 4
H8: Grand Total | I8: 40 | K8: Grand Total | L8: 1 | N8: تم التوقيع | O8: 2 | P8: =GETPIVOTDATA("استجابة العميل",$N$3,"حالة الطلب","تم التسليم") -> 16 | Q8: تم التوقيع | R8: 0.05 | S8: =GETPIVOTDATA("استجابة العميل",$Q$3,"حالة الطلب","تم التسليم") -> 0.4 | T8: حضوري | U8: 7 | W8: (blank) | AG8: مهتم | AH8: 24
N9: سيتم رفع الطلب | O9: 4 | Q9: سيتم رفع الطلب | R9: 0.1 | T9: طلبات الكاسل | U9: 6 | W9: Grand Total | X9: 40 | AG9: (blank)
N10: قبول عرض | O10: 3 | Q10: قبول عرض | R10: 0.075 | T10: قاعدة البيانات | U10: 3 | AG10: Grand Total | AH10: 40
N11: مرفوض | O11: 11 | Q11: مرفوض | R11: 0.275 | T11: (blank)
N12: (blank) | Q12: (blank) | R12: 0 | T12: Grand Total | U12: 40
N13: Grand Total | O13: 40 | Q13: Grand Total | R13: 1
AD14: Values | AN14: المستهدف | AO14: المتحقق | AP14: المتبقي
F15: Count of الاسم | AD15: Average of المتبقي | AE15: 0.6 | AN15: ='data table'!AA1 -> 1000000 | AO15: =SUM(Table2[مبلغ التمويل]) -> 817400 | AP15: =AN15-AO15 -> 182600 | AR15: =AO15/AN15 -> 0.8174
F16: 40 | G16: =GETPIVOTDATA("الاسم",$F$15) -> 40 | AD16: Average of تم_التسليم. | AE16: 0.4 | AF16: =GETPIVOTDATA("Average of تم_التسليم.",$AD$14) -> 0.4
AD17: Average of تسلسل | AE17: 1
I18: Average of مدة المكالمة
I19: 0.006520544 | J19: =GETPIVOTDATA("مدة المكالمة",$I$18) -> 0.006520544
AB22: Row Labels | AC22: Count of تسلسل | AD22: Sum of عدد الاستجابة
AB23: 01-سبتمبر | AC23: 1 | AD23: 1
AB24: 02-سبتمبر | AC24: 4 | AD24: 2
AB25: 03-سبتمبر | AC25: 2 | AD25: 1
AB26: 04-سبتمبر | AC26: 4 | AD26: 4
AB27: 05-سبتمبر | AC27: 2 | AD27: 0
AB28: 06-سبتمبر | AC28: 1 | AD28: 0
AB29: 07-سبتمبر | AC29: 1 | AD29: 1
AB30: 08-سبتمبر | AC30: 2 | AD30: 1
AB31: 09-سبتمبر | AC31: 1 | AD31: 0
AB32: 10-سبتمبر | AC32: 3 | AD32: 3
AB33: 11-سبتمبر | AC33: 1 | AD33: 0
AB34: 12-سبتمبر | AC34: 1 | AD34: 1
... AB47: 25-سبتمبر | AC47: 1 | AD47: 1
AB48: <01/09/2025
AB49: Grand Total | AC49: 40 | AD49: 26

Sheet Sheet5
A2: التاريخ (Day) | B2: All
A4: Sum of عدد الطلبات المستهدفة | B4: Count of رقم الطلب
A5: 1611 | B5: 40

Sheet data table
A1: تسلسل | B1: الاسم | C1: الهوية | D1: رقم الطلب | E1: الجوال | F1: مصدر العميل | G1: طريقة التواصل | H1: المنتج المناسب | I1: استجابة العميل | J1: حالة العميل | K1: حالة الطلب | L1: مبلغ التمويل | M1: مدة المكالمة | N1: التاريخ | O1: اليوم | P1: سبب الرفض | Q1: ملاحظات | R1: تم_التسليم. | S1: المتبقي | T1: عدد الاستجابة | V1: التاريخ | W1: عدد الطلبات المستهدفة | AA1: 1000000
A2: 1 | B2: علي الصحاف | C2: 1094739476 | D2: 1234 | E2: 523698741 | F2: قاعدة البيانات | G2: طلبات الكاسل | H2: تمويل شخصي | I2: استجاب | J2: مهتم | K2: تم التسليم | L2: 12000 | M2: 0.0015393519 | N2: 45901 | O2: =IF(N2="","",TEXT(N2,"dddd")) -> الإثنين | R2: =IF('data table'!$K2="تم التسليم",1,IF('data table'!$K2="", "",0)) -> 1 | S2: =IF(ISBLANK(R2),1,1-R2) -> 0 | T2: =IF(Table2[[#This Row],[استجابة العميل]]="","",IF(Table2[[#This Row],[استجابة العميل]]="استجاب",1,0)) -> 1 | V2: 45901 | W2: 50
A3: 2 | B3: أحمد بن فهد العبدالعزيز | C3: 1094739476 | D3: 5678 | E3: 537826758 | F3: اتصال وارد | G3: حضوري | H3: ايجارة | I3: استجاب | J3: مهتم | K3: تم التسليم | M3: 0.003587963 | N3: 45902 | O3: =IF(N3="","",TEXT(N3,"dddd")) -> الثلاثاء | R3: =IF('data table'!$K3="تم التسليم",1,IF('data table'!$K3="", "",0)) -> 1 | S3: =IF(ISBLANK(R3),1,1-R3) -> 0 | T3: =IF(Table2[[#This Row],[استجابة العميل]]="","",IF(Table2[[#This Row],[استجابة العميل]]="استجاب",1,0)) -> 1 | V3: 45902 | W3: 60
A4: 3 | B4: مروان بن عبدالعزيز بن عبدالله الفداء | C4: 1094739476 | D4: 6844 | E4: 567827667 | F4: طلبات الكاسل | G4: طلبات الكاسل | H4: شراء مديونية | I4: غبر مهم | J4: لم يرد | K4: مرفوض | M4: 0.0071296296 | N4: 45902 | O4: =IF(N4="","",TEXT(N4,"dddd")) -> الثلاثاء | R4: =IF('data table'!$K4="تم التسليم",1,IF('data table'!$K4="", "",0)) -> 0 | S4: =IF(ISBLANK(R4),1,1-R4) -> 1 | T4: =IF(Table2[[#This Row],[استجابة العميل]]="","",IF(Table2[[#This Row],[استجابة العميل]]="استجاب",1,0)) -> 0 | V4: 45903 | W4: 70
A5: 4 | B5: فارس عبدالله ابراهيم المنصور | C5: 1094739476 | D5: 5464 | E5: 918273645 | F5: حضوري | G5: طلبات الكاسل | H5: تمويل إضافي | I5: لم يستجب | J5: لم يرد | K5: مرفوض | M5: 0.0043171296 | N5: 45902 | O5: =IF(N5="","",TEXT(N5,"dddd")) -> الثلاثاء | R5: =IF('data table'!$K5="تم التسليم",1,IF('data table'!$K5="", "",0)) -> 0 | S5: =IF(ISBLANK(R5),1,1-R5) -> 1 | T5: =IF(Table2[[#This Row],[استجابة العميل]]="","",IF(Table2[[#This Row],[استجابة العميل]]="استجاب",1,0)) -> 0 | V5: 45904 | W5: 80
A6: 5 | B6: عبدالعزيز عبدالله علي الغامدي | C6: 1094739476 | D6: 8441 | E6: 203948576 | F6: إحالة من عميل | G6: اتصال وارد | H6: ايجارة | I6: استجاب | J6: مهتم | K6: تم التسليم | L6: 85000 | M6: 0.0057638889 | N6: 45902 | O6: =IF(N6="","",TEXT(N6,"dddd")) -> الثلاثاء | R6: =IF('data table'!$K6="تم التسليم",1,IF('data table'!$K6="", "",0)) -> 1 | S6: =IF(ISBLANK(R6),1,1-R6) -> 0 | T6: =IF(Table2[[#This Row],[استجابة العميل]]="","",IF(Table2[[#This Row],[استجابة العميل]]="استجاب",1,0)) -> 1 | V6: 45905 | W6: 15
A7: 6 | B7: اثير عبدالعزيز سعد السيف | C7: 1094739476 | D7: 8411 | E7: 657382910 | F7: بحث شخصي | G7: إحالة من عميل | H7: شراء مديونية | I7: استجاب | J7: مهتم | K7: بانتظار المستندات | M7: 0.006400463 | N7: 45903 | O7: =IF(N7="","",TEXT(N7,"dddd")) -> الأربعاء | R7: =IF('data table'!$K7="تم التسليم",1,IF('data table'!$K7="", "",0)) -> 0 | S7: =IF(ISBLANK(R7),1,1-R7) -> 1 | T7: =IF(Table2[[#This Row],[استجابة العميل]]="","",IF(Table2[[#This Row],[استجابة العميل]]="استجاب",1,0)) -> 1 | V7: 45906 | W7: 20
A8: 7 | B8: محمد بن علي بن محمد التويجري | C8: 1094739476 | D8: 5741 | E8: 481920374 | F8: CRM | G8: بحث شخصي | H8: تمويل إضافي | I8: لم يستجب | J8: المتابعة لاحقاً | K8: سيتم رفع الطلب | M8: 0.012581019 | N8: 45903 | O8: =IF(N8="","",TEXT(N8,"dddd")) -> الأربعاء | R8: =IF('data table'!$K8="تم التسليم",1,IF('data table'!$K8="", "",0)) -> 0 | S8: =IF(ISBLANK(R8),1,1-R8) -> 1 | T8: =IF(Table2[[#This Row],[استجابة العميل]]="","",IF(Table2[[#This Row],[استجابة العميل]]="استجاب",1,0)) -> 0 | V8: 45907 | W8: 30
A9: 8 | B9: علي بن محمد بن علي السلامه | C9: 1094739476 | D9: 1221 | E9: 739105826 | F9: بحث شخصي | G9: طلبات الكاسل | H9: ايجارة | I9: استجاب | J9: مهتم | K9: تم التسليم | L9: 15000 | M9: 0.0025694444 | N9: 45904 | O9: =IF(N9="","",TEXT(N9,"dddd")) -> الخميس | R9: =IF('data table'!$K9="تم التسليم",1,IF('data table'!$K9="", "",0)) -> 1 | S9: =IF(ISBLANK(R9),1,1-R9) -> 0 | T9: =IF(Table2[[#This Row],[استجابة العميل]]="","",IF(Table2[[#This Row],[استجابة العميل]]="استجاب",1,0)) -> 1 | V9: 45908 | W9: 90
A10: 9 | B10: عبدالله بن سعود عبدالعزيز الهزاع | C10: 1094739476 | D10: 2211 | E10: 120938475 | F10: إحالة من عميل | G10: إحالة من عميل | H10: تمويل إضافي | I10: استجاب | J10: مهتم | K10: قبول عرض | M10: 0.0089699074 | N10: 45904 | O10: =IF(N10="","",TEXT(N10,"dddd")) -> الخميس | R10: =IF('data table'!$K10="تم التسليم",1,IF('data table'!$K10="", "",0)) -> 0 | S10: =IF(ISBLANK(R10),1,1-R10) -> 1 | T10: =IF(Table2[[#This Row],[استجابة العميل]]="","",IF(Table2[[#This Row],[استجابة العميل]]="استجاب",1,0)) -> 1 | V10: 45909 | W10: 100
A11: 10 | B11: شاهين بن عامر بن علي المطيري | C11: 1094739476 | D11: 8442 | E11: 564738291 | F11: حضوري | G11: اتصال وارد | H11: شراء مديونية | I11: استجاب | J11: مهتم | K11: تم التسليم | L11: 52100 | M11: 0.00041666667 | N11: 45904 | O11: =IF(N11="","",TEXT(N11,"dddd")) -> الخميس | R11: =IF('data table'!$K11="تم التسليم",1,IF('data table'!$K11="", "",0)) -> 1 | S11: =IF(ISBLANK(R11),1,1-R11) -> 0 | T11: =IF(Table2[[#This Row],[استجابة العميل]]="","",IF(Table2[[#This Row],[استجابة العميل]]="استجاب",1,0)) -> 1 | V11: 45910 | W11: 60
A12: 11 | B12: عبدالعزيز رجب عبدالعزيز جبارة | C12: 1094739476 | D12: 9845 | E12: 849102736 | F12: اتصال وارد | G12: إحالة من عميل | H12: تمويل إضافي | I12: استجاب | J12: مهتم | K12: تم التسليم | L12: 49000 | M12: 0.013923611 | N12: 45904 | O12: =IF(N12="","",TEXT(N12,"dddd")) -> الخميس | R12: =IF('data table'!$K12="تم التسليم",1,IF('data table'!$K12="", "",0)) -> 1 | S12: =IF(ISBLANK(R12),1,1-R12) -> 0 | T12: =IF(Table2[[#This Row],[استجابة العميل]]="","",IF(Table2[[#This Row],[استجابة العميل]]="استجاب",1,0)) -> 1 | V12: 45911 | W12: 22
A13: 12 | B13: نورة بنت عبدالله العتيبي | C13: 1094739476 | D13: 1568 | E13: 374829105 | F13: طلبات الكاسل | G13: طلبات الكاسل | H13: تمويل إضافي | I13: لم يستجب | J13: المتابعة لاحقاً | K13: سيتم رفع الطلب | M13: 0.0050810185 | N13: 45905 | O13: =IF(N13="","",TEXT(N13,"dddd")) -> الجمعة | R13: =IF('data table'!$K13="تم التسليم",1,IF('data table'!$K13="", "",0)) -> 0 | S13: =IF(ISBLANK(R13),1,1-R13) -> 1 | T13: =IF(Table2[[#This Row],[استجابة العميل]]="","",IF(Table2[[#This Row],[استجابة العميل]]="استجاب",1,0)) -> 0 | V13: 45912 | W13: 89
A14: 13 | B14: محمد بن علي بن محمد التويجري | C14: 1094739476 | D14: 3695 | E14: 910283746 | F14: قاعدة البيانات | G14: بحث شخصي | H14: ايجارة | I14: لم يستجب | J14: غير مهتم | K14: مرفوض | M14: 0.010972222 | N14: 45905 | O14: =IF(N14="","",TEXT(N14,"dddd")) -> الجمعة | R14: =IF('data table'!$K14="تم التسليم",1,IF('data table'!$K14="", "",0)) -> 0 | S14: =IF(ISBLANK(R14),1,1-R14) -> 1 | T14: =IF(Table2[[#This Row],[استجابة العميل]]="","",IF(Table2[[#This Row],[استجابة العميل]]="استجاب",1,0)) -> 0 | V14: 45913 | W14: 70
A15: 14 | B15: فاطمة بنت عبدالله المنصور | C15: 1094739476 | D15: 3652 | E15: 657483920 | F15: CRM | G15: اتصال وارد | H15: ايجارة | I15: غبر مهم | J15: الرقم غير صحيح | K15: مرفوض | M15: 0.0062962963 | N15: 45906 | O15: =IF(N15="","",TEXT(N15,"dddd")) -> السبت | R15: =IF('data table'!$K15="تم التسليم",1,IF('data table'!$K15="", "",0)) -> 0 | S15: =IF(ISBLANK(R15),1,1-R15) -> 1 | T15: =IF(Table2[[#This Row],[استجابة العميل]]="","",IF(Table2[[#This Row],[استجابة العميل]]="استجاب",1,0)) -> 0 | V15: 45914 | W15: 40
A16: 15 | B16: ياسر الهزاع | C16: 1094739476 | D16: 8461 | E16: 382910475 | F16: طلبات الكاسل | G16: طلبات الكاسل | H16: ايجارة | I16: استجاب | J16: مهتم | K16: تم التسليم | L16: 87000 | M16: 0.0017476852 | N16: 45907 | O16: =IF(N16="","",TEXT(N16,"dddd")) -> الأحد | R16: =IF('data table'!$K16="تم التسليم",1,IF('data table'!$K16="", "",0)) -> 1 | S16: =IF(ISBLANK(R16),1,1-R16) -> 0 | T16: =IF(Table2[[#This Row],[استجابة العميل]]="","",IF(Table2[[#This Row],[استجابة العميل]]="استجاب",1,0)) -> 1 | V16: 45915 | W16: 30
A17: 16 | B17: رائد بن ماجد بن حمدان الشهري | C17: 1094739476 | D17: 5678 | E17: 746291038 | F17: طلبات الكاسل | G17: حضوري | H17: تمويل إضافي | I17: استجاب | J17: مهتم | K17: سيتم رفع الطلب | M17: 0.010034722 | N17: 45908 | O17: =IF(N17="","",TEXT(N17,"dddd")) -> الإثنين | R17: =IF('data table'!$K17="تم التسليم",1,IF('data table'!$K17="", "",0)) -> 0 | S17: =IF(ISBLANK(R17),1,1-R17) -> 1 | T17: =IF(Table2[[#This Row],[استجابة العميل]]="","",IF(Table2[[#This Row],[استجابة العميل]]="استجاب",1,0)) -> 1 | V17: 45916 | W17: 26
A18: 17 | B18: مروان بن محمد بن منصور الشمراني | C18: 1094739476 | D18: 8563 | E18: 192837465 | F18: إحالة من عميل | G18: طلبات الكاسل | H18: شراء مديونية | I18: لم يستجب | J18: غير مهتم | K18: مرفوض | M18: 0.013865741 | N18: 45908 | O18: =IF(N18="","",TEXT(N18,"dddd")) -> الإثنين | R18: =IF('data table'!$K18="تم التسليم",1,IF('data table'!$K18="", "",0)) -> 0 | S18: =IF(ISBLANK(R18),1,1-R18) -> 1 | T18: =IF(Table2[[#This Row],[استجابة العميل]]="","",IF(Table2[[#This Row],[استجابة العميل]]="استجاب",1,0)) -> 0 | V18: 45917 | W18: 33
A19: 18 | B19: سعد فهد البقمي | C19: 1094739476 | D19: 5460 | E19: 839201746 | F19: CRM | G19: اتصال وارد | H19: ايجارة | I19: غبر مهم | J19: الرقم غير صحيح | K19: مرفوض | M19: 0.0035416667 | N19: 45909 | O19: =IF(N19="","",TEXT(N19,"dddd")) -> الثلاثاء | R19: =IF('data table'!$K19="تم التسليم",1,IF('data table'!$K19="", "",0)) -> 0 | S19: =IF(ISBLANK(R19),1,1-R19) -> 1 | T19: =IF(Table2[[#This Row],[استجابة العميل]]="","",IF(Table2[[#This Row],[استجابة العميل]]="استجاب",1,0)) -> 0 | V19: 45918 | W19: 54
A20: 19 | B20: علي بن جابر بن فهد الحربي | C20: 1094739476 | D20: 1568 | E20: 475829103 | F20: حضوري | G20: اتصال وارد | H20: تمويل إضافي | I20: استجاب | J20: مهتم | K20: تم التسليم | L20: 52100 | M20: 0.0080902778 | N20: 45910 | O20: =IF(N20="","",TEXT(N20,"dddd")) -> الأربعاء | R20: =IF('data table'!$K20="تم التسليم",1,IF('data table'!$K20="", "",0)) -> 1 | S20: =IF(ISBLANK(R20),1,1-R20) -> 0 | T20: =IF(Table2[[#This Row],[استجابة العميل]]="","",IF(Table2[[#This Row],[استجابة العميل]]="استجاب",1,0)) -> 1 | V20: 45919 | W20: 95
A21: 20 | B21: سلمى سالم السلامه | C21: 1094739476 | D21: 5658 | E21: 102938475 | F21: إحالة من عميل | G21: إحالة من عميل | H21: شراء مديونية | I21: استجاب | J21: مهتم | K21: الائتمان | M21: 0.0058101852 | N21: 45910 | O21: =IF(N21="","",TEXT(N21,"dddd")) -> الأربعاء | R21: =IF('data table'!$K21="تم التسليم",1,IF('data table'!$K21="", "",0)) -> 0 | S21: =IF(ISBLANK(R21),1,1-R21) -> 1 | T21: =IF(Table2[[#This Row],[استجابة العميل]]="","",IF(Table2[[#This Row],[استجابة العميل]]="استجاب",1,0)) -> 1 | V21: 45920 | W21: 23
A22: 21 | B22: أميرة علي المنصور | C22: 1094739476 | D22: 8471 | E22: 564738920 | F22: إحالة من عميل | G22: بحث شخصي | H22: تمويل شخصي | I22: استجاب | J22: مهتم | K22: تم التسليم | L22: 52000 | M22: 0.0034375 | N22: 45910 | O22: =IF(N22="","",TEXT(N22,"dddd")) -> الأربعاء | R22: =IF('data table'!$K22="تم التسليم",1,IF('data table'!$K22="", "",0)) -> 1 | S22: =IF(ISBLANK(R22),1,1-R22) -> 0 | T22: =IF(Table2[[#This Row],[استجابة العميل]]="","",IF(Table2[[#This Row],[استجابة العميل]]="استجاب",1,0)) -> 1 | V22: 45921 | W22: 20
A23: 22 | B23: مروه حمود الفداء | C23: 1094739476 | D23: 5638 | E23: 918374652 | F23: طلبات الكاسل | G23: طلبات الكاسل | H23: تمويل إضافي | I23: غبر مهم | J23: الرقم غير صحيح | K23: مرفوض | M23: 0.011238426 | N23: 45911 | O23: =IF(N23="","",TEXT(N23,"dddd")) -> الخميس | R23: =IF('data table'!$K23="تم التسليم",1,IF('data table'!$K23="", "",0)) -> 0 | S23: =IF(ISBLANK(R23),1,1-R23) -> 1 | T23: =IF(Table2[[#This Row],[استجابة العميل]]="","",IF(Table2[[#This Row],[استجابة العميل]]="استجاب",1,0)) -> 0 | V23: 45922 | W23: 80
A24: 23 | B24: عمر الشريف | C24: 1094739476 | D24: 3682 | E24: 203948571 | F24: إحالة من عميل | G24: قاعدة البيانات | H24: شراء مديونية | I24: استجاب | J24: المتابعة لاحقاً | K24: بانتظار المستندات | M24: 0.0074652778 | N24: 45912 | O24: =IF(N24="","",TEXT(N24,"dddd")) -> الجمعة | R24: =IF('data table'!$K24="تم التسليم",1,IF('data table'!$K24="", "",0)) -> 0 | S24: =IF(ISBLANK(R24),1,1-R24) -> 1 | T24: =IF(Table2[[#This Row],[استجابة العميل]]="","",IF(Table2[[#This Row],[استجابة العميل]]="استجاب",1,0)) -> 1 | V24: 45923 | W24: 10
A25: 24 | B25: ماهر بن عبدالعزيز بن حسن الفداء | C25: 1094739476 | D25: 1251 | E25: 657382914 | F25: CRM | G25: طلبات الكاسل | H25: تمويل إضافي | I25: غبر مهم | J25: لم يرد | K25: مرفوض | M25: 0.0043171296 | N25: 45913 | O25: =IF(N25="","",TEXT(N25,"dddd")) -> السبت | R25: =IF('data table'!$K25="تم التسليم",1,IF('data table'!$K25="", "",0)) -> 0 | S25: =IF(ISBLANK(R25),1,1-R25) -> 1 | T25: =IF(Table2[[#This Row],[استجابة العميل]]="","",IF(Table2[[#This Row],[استجابة العميل]]="استجاب",1,0)) -> 0 | V25: 45924 | W25: 110
A26: 25 | B26: حمد الدوسري | C26: 1094739476 | D26: 5469 | E26: 481920379 | F26: حضوري | G26: إحالة من عميل | H26: ايجارة | I26: استجاب | J26: مهتم | K26: تم التسليم | L26: 69000 | M26: 0.0090509259 | N26: 45914 | O26: =IF(N26="","",TEXT(N26,"dddd")) -> الأحد | R26: =IF('data table'!$K26="تم التسليم",1,IF('data table'!$K26="", "",0)) -> 1 | S26: =IF(ISBLANK(R26),1,1-R26) -> 0 | T26: =IF(Table2[[#This Row],[استجابة العميل]]="","",IF(Table2[[#This Row],[استجابة العميل]]="استجاب",1,0)) -> 1 | V26: 45925 | W26: 77
A27: 26 | B27: سلمى القحطاني | C27: 1094739476 | D27: 1652 | E27: 739105824 | F27: إحالة من عميل | G27: اتصال وارد | H27: تمويل شخصي | I27: استجاب | J27: غير مهتم | K27: قبول عرض | M27: 0.0013773148 | N27: 45914 | O27: =IF(N27="","",TEXT(N27,"dddd")) -> الأحد | R27: =IF('data table'!$K27="تم التسليم",1,IF('data table'!$K27="", "",0)) -> 0 | S27: =IF(ISBLANK(R27),1,1-R27) -> 1 | T27: =IF(Table2[[#This Row],[استجابة العميل]]="","",IF(Table2[[#This Row],[استجابة العميل]]="استجاب",1,0)) -> 1 | V27: 45926 | W27: 55
A28: 27 | B28: سارة الحارثي | C28: 1094739476 | D28: 5648 | E28: 120938479 | F28: إحالة من عميل | G28: بحث شخصي | H28: ايجارة | I28: لم يستجب | J28: المتابعة لاحقاً | K28: مرفوض | M28: 0.0121875 | N28: 45914 | O28: =IF(N28="","",TEXT(N28,"dddd")) -> الأحد | R28: =IF('data table'!$K28="تم التسليم",1,IF('data table'!$K28="", "",0)) -> 0 | S28: =IF(ISBLANK(R28),1,1-R28) -> 1 | T28: =IF(Table2[[#This Row],[استجابة العميل]]="","",IF(Table2[[#This Row],[استجابة العميل]]="استجاب",1,0)) -> 0 | V28: 45927 | W28: 36
A29: 28 | B29: ضحى الشمراني | C29: 1094739476 | D29: 8481 | E29: 564738295 | F29: قاعدة البيانات | G29: بحث شخصي | H29: تمويل إضافي | I29: استجاب | J29: مهتم | K29: تم التسليم | L29: 44800 | M29: 0.00013888889 | N29: 45914 | O29: =IF(N29="","",TEXT(N29,"dddd")) -> الأحد | R29: =IF('data table'!$K29="تم التسليم",1,IF('data table'!$K29="", "",0)) -> 1 | S29: =IF(ISBLANK(R29),1,1-R29) -> 0 | T29: =IF(Table2[[#This Row],[استجابة العميل]]="","",IF(Table2[[#This Row],[استجابة العميل]]="استجاب",1,0)) -> 1 | V29: 45928 | W29: 68
A30: 29 | B30: ماجد البقمي | C30: 1094739476 | D30: 1234 | E30: 849102739 | F30: اتصال وارد | G30: اتصال وارد | H30: شراء مديونية | I30: غبر مهم | J30: الرقم غير صحيح | K30: مرفوض | M30: 0.0054513889 | N30: 45915 | O30: =IF(N30="","",TEXT(N30,"dddd")) -> الإثنين | R30: =IF('data table'!$K30="تم التسليم",1,IF('data table'!$K30="", "",0)) -> 0 | S30: =IF(ISBLANK(R30),1,1-R30) -> 1 | T30: =IF(Table2[[#This Row],[استجابة العميل]]="","",IF(Table2[[#This Row],[استجابة العميل]]="استجاب",1,0)) -> 0 | V30: 45929 | W30: 78
A31: 30 | B31: سليمان المطيري | C31: 1094739476 | D31: 8415 | E31: 374829109 | F31: طلبات الكاسل | G31: إحالة من عميل | H31: ايجارة | I31: استجاب | J31: مهتم | K31: تم التوقيع | M31: 0.0039814815 | N31: 45915 | O31: =IF(N31="","",TEXT(N31,"dddd")) -> الإثنين | R31: =IF('data table'!$K31="تم التسليم",1,IF('data table'!$K31="", "",0)) -> 0 | S31: =IF(ISBLANK(R31),1,1-R31) -> 1 | T31: =IF(Table2[[#This Row],[استجابة العميل]]="","",IF(Table2[[#This Row],[استجابة العميل]]="استجاب",1,0)) -> 1 | V31: 45930 | W31: 20
A32: 31 | B32: سليمان حمود الهزاع | C32: 1094739476 | D32: 3697 | E32: 910283749 | F32: حضوري | G32: طلبات الكاسل | H32: ايجارة | I32: لم يستجب | J32: المتابعة لاحقاً | K32: تم التسليم | L32: 52100 | M32: 0.0014814815 | N32: 45916 | O32: =IF(N32="","",TEXT(N32,"dddd")) -> الثلاثاء | R32: =IF('data table'!$K32="تم التسليم",1,IF('data table'!$K32="", "",0)) -> 1 | S32: =IF(ISBLANK(R32),1,1-R32) -> 0 | T32: =IF(Table2[[#This Row],[استجابة العميل]]="","",IF(Table2[[#This Row],[استجابة العميل]]="استجاب",1,0)) -> 0
A33: 32 | B33: عمر بن سلمان بن سلمان الحارثي | C33: 1094739476 | D33: 8421 | E33: 657483924 | F33: إحالة من عميل | G33: بحث شخصي | H33: تمويل شخصي | I33: استجاب | J33: مهتم | K33: سيتم رفع الطلب | M33: 0.012835648 | N33: 45917 | O33: =IF(N33="","",TEXT(N33,"dddd")) -> الأربعاء | R33: =IF('data table'!$K33="تم التسليم",1,IF('data table'!$K33="", "",0)) -> 0 | S33: =IF(ISBLANK(R33),1,1-R33) -> 1 | T33: =IF(Table2[[#This Row],[استجابة العميل]]="","",IF(Table2[[#This Row],[استجابة العميل]]="استجاب",1,0)) -> 1
A34: 33 | B34: بسمة الغامدي | C34: 1094739476 | D34: 1568 | E34: 382910479 | F34: حضوري | G34: اتصال وارد | H34: تمويل إضافي | I34: استجاب | J34: مهتم | K34: قبول عرض | M34: 0.0084143519 | N34: 45918 | O34: =IF(N34="","",TEXT(N34,"dddd")) -> الخميس | R34: =IF('data table'!$K34="تم التسليم",1,IF('data table'!$K34="", "",0)) -> 0 | S34: =IF(ISBLANK(R34),1,1-R34) -> 1 | T34: =IF(Table2[[#This Row],[استجابة العميل]]="","",IF(Table2[[#This Row],[استجابة العميل]]="استجاب",1,0)) -> 1
A35: 34 | B35: نجلاء جابر الحارثي | C35: 1094739476 | D35: 6444 | E35: 746291032 | F35: إحالة من عميل | G35: طلبات الكاسل | H35: شراء مديونية | I35: استجاب | J35: مهتم | K35: تم التسليم | L35: 49000 | M35: 0.0022569444 | N35: 45919 | O35: =IF(N35="","",TEXT(N35,"dddd")) -> الجمعة | R35: =IF('data table'!$K35="تم التسليم",1,IF('data table'!$K35="", "",0)) -> 1 | S35: =IF(ISBLANK(R35),1,1-R35) -> 0 | T35: =IF(Table2[[#This Row],[استجابة العميل]]="","",IF(Table2[[#This Row],[استجابة العميل]]="استجاب",1,0)) -> 1
A36: 35 | B36: محمد بن علي العبدالله | C36: 1094739476 | D36: 4589 | E36: 192837469 | F36: بحث شخصي | G36: قاعدة البيانات | H36: تمويل شخصي | I36: استجاب | J36: مهتم | K36: تم التسليم | L36: 65000 | M36: 0.0066782407 | N36: 45920 | O36: =IF(N36="","",TEXT(N36,"dddd")) -> السبت | R36: =IF('data table'!$K36="تم التسليم",1,IF('data table'!$K36="", "",0)) -> 1 | S36: =IF(ISBLANK(R36),1,1-R36) -> 0 | T36: =IF(Table2[[#This Row],[استجابة العميل]]="","",IF(Table2[[#This Row],[استجابة العميل]]="استجاب",1,0)) -> 1
A37: 36 | B37: محمد بن عبدالله العبدالله | C37: 1094739476 | D37: 6251 | E37: 839201742 | F37: CRM | G37: بحث شخصي | H37: تمويل إضافي | I37: استجاب | J37: مهتم | K37: تم التسليم | L37: 33300 | M37: 0.0097569444 | N37: 45921 | O37: =IF(N37="","",TEXT(N37,"dddd")) -> الأحد | R37: =IF('data table'!$K37="تم التسليم",1,IF('data table'!$K37="", "",0)) -> 1 | S37: =IF(ISBLANK(R37),1,1-R37) -> 0 | T37: =IF(Table2[[#This Row],[استجابة العميل]]="","",IF(Table2[[#This Row],[استجابة العميل]]="استجاب",1,0)) -> 1
A38: 37 | B38: محمد بن سعود العبدالله | C38: 1094739476 | D38: 3842 | E38: 475829107 | F38: بحث شخصي | G38: اتصال وارد | H38: ايجارة | I38: استجاب | J38: مهتم | K38: تم التوقيع | M38: 0.0030208333 | N38: 45922 | O38: =IF(N38="","",TEXT(N38,"dddd")) -> الإثنين | R38: =IF('data table'!$K38="تم التسليم",1,IF('data table'!$K38="", "",0)) -> 0 | S38: =IF(ISBLANK(R38),1,1-R38) -> 1 | T38: =IF(Table2[[#This Row],[استجابة العميل]]="","",IF(Table2[[#This Row],[استجابة العميل]]="استجاب",1,0)) -> 1
A39: 38 | B39: أحمد بن خالد العبدالعزيز | C39: 1094739476 | D39: 9871 | E39: 102938479 | F39: إحالة من عميل | G39: إحالة من عميل | H39: شراء مديونية | I39: استجاب | J39: مهتم | K39: التحقق | M39: 0.013310185 | N39: 45923 | O39: =IF(N39="","",TEXT(N39,"dddd")) -> الثلاثاء | R39: =IF('data table'!$K39="تم التسليم",1,IF('data table'!$K39="", "",0)) -> 0 | S39: =IF(ISBLANK(R39),1,1-R39) -> 1 | T39: =IF(Table2[[#This Row],[استجابة العميل]]="","",IF(Table2[[#This Row],[استجابة العميل]]="استجاب",1,0)) -> 1
A40: 39 | B40: نورة بنت سعود العتيبي | C40: 1094739476 | D40: 9872 | E40: 564738925 | F40: حضوري | G40: بحث شخصي | H40: تمويل إضافي | I40: غبر مهم | J40: لم يرد | K40: مرفوض | M40: 0.004837963 | N40: 45924 | O40: =IF(N40="","",TEXT(N40,"dddd")) -> الأربعاء | R40: =IF('data table'!$K40="تم التسليم",1,IF('data table'!$K40="", "",0)) -> 0 | S40: =IF(ISBLANK(R40),1,1-R40) -> 1 | T40: =IF(Table2[[#This Row],[استجابة العميل]]="","",IF(Table2[[#This Row],[استجابة العميل]]="استجاب",1,0)) -> 0
...
